Workbook
Name scen_name: 'Dashboard'!$B$5
Name scen_sel: 'Dashboard'!$P$4
Name px_now: 'Inputs'!$D$6
Name shares_basic: 'Inputs'!$D$7
Name dilution: 'Inputs'!$D$8
Name dps: 'Inputs'!$D$9
Name rf: 'Inputs'!$D$11
Name rm: 'Inputs'!$D$12
Name crp: 'Inputs'!$D$13
Name size_prem: 'Inputs'!$D$14
Name beta_src: 'Inputs'!$D$15
Name beta_raw: 'Inputs'!$D$16
Name beta_daily_in: 'Inputs'!$D$17
Name beta_crsp: 'Inputs'!$D$18
Name beta_custom: 'Inputs'!$D$19
Name beta_bu: 'Inputs'!$D$20
Name kd: 'Inputs'!$D$21
Name t_marg: 'Inputs'!$D$22
Name g: 'Inputs'!$D$24
Name first_period: 'Inputs'!$D$25
Name stub: 'Inputs'!$D$26
Name midyear: 'Inputs'!$D$27
Name band: 'Inputs'!$D$29
Name horizon: 'Inputs'!$D$30
Name reg_min: 'Inputs'!$D$31
Name eq_gate: 'Inputs'!$D$32
Name rev_y0: 'Inputs'!$D$34
Name corp_pct: 'Inputs'!$D$35
Name tax_y1: 'Inputs'!$D$36
Name tax_lr: 'Inputs'!$D$37
Name da_pct: 'Inputs'!$D$38
Name capex_pct: 'Inputs'!$D$39
Name nwc_pct: 'Inputs'!$D$40
Name nwc_open: 'Inputs'!$D$41
Name ronic: 'Inputs'!$D$42
Name exit_mult: 'Inputs'!$D$43
Name tv_method: 'Inputs'!$D$44
Name segy1_total: 'Inputs'!$D$45
Name cash: 'Inputs'!$D$47
Name core_debt: 'Inputs'!$D$48
Name leases: 'Inputs'!$D$49
Name dfs_rec: 'Inputs'!$D$50
Name dfs_le: 'Inputs'!$D$51
Name dfs_debt: 'Inputs'!$D$52
Name investments: 'Inputs'!$D$53
Name nci: 'Inputs'!$D$54
Name s_g_total_0: 'Scenarios'!$E$5
Name s_g_total_1: 'Scenarios'!$E$6
Name s_g_total_2: 'Scenarios'!$E$7
Name s_g_total_3: 'Scenarios'!$E$8
Name s_m0_total: 'Scenarios'!$E$9
Name s_m1_total: 'Scenarios'!$E$10
Name eq_m: '1 History'!$D$43
Name eq_accr: '1 History'!$B$45
Name eq_cc: '1 History'!$B$46
Name eq_red: '1 History'!$B$47
Name eq_amber: '1 History'!$B$48
Name eq_grade: '1 History'!$B$49
Name cf_last_nopat: '2 Cash flows'!$M$16
Name cf_last_ebitda: '2 Cash flows'!$M$21

Sheet Dashboard
B1: Sandisk Corporation · SNDK
B2: Valuation framework · FCFF DCF · valuation date 2026-10-20 · USD millions except per share
T3: chart data (live)
B4: SCENARIO | P4: =IF(scen_name="Bear",1,IF(scen_name="Bull",3,2)) | T4: Method | U4: Value | V4: Price
B5: Base | C5: ◂ pick Bear, Base or Bull; every sheet re-values | T5: DCF | U5: =model_ps | V5: =px_now
T6: Monte Carlo | U6: ='6 Verdict'!B6 | V6: =px_now
B7: FAIR VALUE / SHARE | D7: SHARE PRICE | F7: UPSIDE | H7: CALL | J7: EXPECTED ALPHA | L7: DISCOUNT RATE | N7: EARNINGS QUALITY | T7: Comps | U7: =comps_ps | V7: =px_now
B8: =fair | D8: =px_now | F8: =upside | H8: =v_call | J8: =alpha | L8: =disc_rate | N8: =eq_grade | T8: Regression | U8: =IF(ISNUMBER(reg_ps),reg_ps,0) | V8: =px_now
B9: blended, step 6 | D9: 2026-10-20 | F9: fair ÷ price − 1 | H9: ±10% band | J9: 1-year, vs Ke | L9: WACC | N9: grade A–D, step 1 | T9: Blended | U9: =fair | V9: =px_now
T11: Present value of
T12: Forecast years | U12: =pv_sum
T13: Terminal value | U13: =pv_tv
B31: HOW TO USE
B32: 1 History | C32: historic performance and earnings quality
B33: 2 Cash flows | C33: the forecast that produces the cash flows
B34: 3 Discount rate | C34: rf, Rm, MRP, beta from daily returns, Ke, WACC
B35: 4 Discount | C35: present values and the terminal value
B36: 5 Price | C36: enterprise value → equity value → ÷ shares → price
B37: 6 Verdict | C37: methods blended into the call and expected alpha
B38: Inputs | C38: every input: pulled value, your value (yellow), source
B39: Scenarios | C39: Bear / Base / Bull drivers
B41: COLOUR CODE
B42: 123 | C42: blue: typed input or pulled data
B43: 123 | C43: black: formula
C44: yellow: your value (overrides the pulled one)
C45: pale blue: key result of a step
B47: SOURCES
B48: Price, market cap, shares, beta (5Y), forward P/E, EV multiples, debt, cash, EBITDA, revenue (TTM), targets | I48: Yahoo Finance quoteSummary, 2026-10-20
B49: Annual and quarterly statements | I49: Yahoo Finance fundamentals-timeseries, 2026-10-20
B50: Daily prices and beta regression | I50: Yahoo Finance chart API (adjusted closes) for SNDK and ^GSPC, 2025-02-14 to 2026-10-20
B51: Risk-free rate | I51: ^TNX (10-year Treasury yield) 5.117%, 2026-10-20
B52: Equity risk premium | I52: Damodaran implied ERP, Jan-2026 (assumption, editable)
B53: Cost of debt | I53: Synthetic rating AAA from interest coverage 170.8x (Damodaran large-firm table)
B54: Peers | I54: Yahoo related symbols: 000660.KS, 005930.KS, 285A.T, MU, STX, WDC

Sheet Inputs
A1: Inputs
A2: Yellow = type your own value to override the pulled one. Column D is what every formula uses.
A4: Input | B4: Pulled value | C4: Your value | D4: Value used | E4: Unit | F4: Origin | G4: Source / basis
A5: Market
A6: Share price | B6: 1365.38 | D6: =IF(ISBLANK(C6),B6,C6) | E6: $ | F6: sourced | G6: Yahoo Finance quoteSummary price.regularMarketPrice
A7: Shares outstanding | B7: 144.52756 | D7: =IF(ISBLANK(C7),B7,C7) | E7: m | F7: sourced | G7: Yahoo Finance quoteSummary defaultKeyStatistics.impliedSharesOutstanding (checked against marketCap ÷ price)
A8: Dilution (options, RSUs) | B8: 11 | D8: =IF(ISBLANK(C8),B8,C8) | E8: m | F8: derived | G8: Yahoo Finance fundamentals (quarterly): diluted average shares − ordinary shares, latest quarter
A9: Dividend per share (for expected return) | B9: 0 | D9: =IF(ISBLANK(C9),B9,C9) | E9: $ | F9: sourced | G9: Yahoo Finance quoteSummary summaryDetail.dividendRate
A10: Cost of capital
A11: Risk-free rate: 10-year Treasury yield | B11: 0.05117 | D11: =IF(ISBLANK(C11),B11,C11) | E11: % | F11: sourced | G11: ^TNX 10-year Treasury yield, Yahoo chart API
A12: Expected market return (Rm) | B12: 0.09347 | D12: =IF(ISBLANK(C12),B12,C12) | E12: % | F12: assumption | G12: rf + ERP
A13: Country risk premium | B13: 0 | D13: =IF(ISBLANK(C13),B13,C13) | E13: % | F13: assumption | G13: 0 (US)
A14: Size premium | B14: 0 | D14: =IF(ISBLANK(C14),B14,C14) | E14: % | F14: setting
A15: Beta used: daily_adj, daily, blume, raw, crsp_monthly(_adj), bottom_up, custom | B15: daily_adj | D15: =IF(ISBLANK(C15),B15,C15) | F15: setting
A16: Beta, published 5-year monthly | B16: 2.8511471 | D16: =IF(ISBLANK(C16),B16,C16) | F16: sourced | G16: Yahoo Finance quoteSummary summaryDetail.beta (5Y monthly)
A17: Beta, daily regression (used only if Beta data is empty) | B17: 2.8511471 | D17: =IF(ISBLANK(C17),B17,C17) | F17: setting
A18: Beta, CRSP monthly regression | D18: =IF(ISBLANK(C18),B18,C18) | F18: setting
A19: Beta, custom | B19: 2.8511471 | D19: =IF(ISBLANK(C19),B19,C19) | F19: derived | G19: copy of daily regression beta
A20: Beta, bottom-up from peers (relevered) | B20: 2.1555563 | D20: =IF(ISBLANK(C20),B20,C20) | F20: formula | G20: median unlevered peer beta, relevered at this company's D/E
A21: Pre-tax cost of debt | B21: 0.05707 | D21: =IF(ISBLANK(C21),B21,C21) | E21: % | F21: derived | G21: rf + AAA spread; coverage = operating income ÷ interest expense
A22: Marginal tax rate | B22: 0.21 | D22: =IF(ISBLANK(C22),B22,C22) | E22: % | F22: assumption | G22: 21% US federal statutory rate
A23: Timing and terminal
A24: Terminal growth | B24: 0.03 | D24: =IF(ISBLANK(C24),B24,C24) | E24: % | F24: assumption | G24: 3%, capped at rf − 1%
A25: Years from today to the first fiscal year end | B25: 0.7008898 | D25: =IF(ISBLANK(C25),B25,C25) | E25: yrs | F25: derived | G25: days from 2026-10-20 to fiscal year end 2027-07-03
A26: Share of the first year after the last balance sheet | B26: 1 | D26: =IF(ISBLANK(C26),B26,C26) | F26: derived | G26: share of the year after the last balance sheet (2026-06-30)
A27: Mid-year convention (1 = yes, 0 = year-end) | B27: 1 | D27: =IF(ISBLANK(C27),B27,C27) | F27: setting
A28: Verdict
A29: Fairly-valued band (±) | B29: 0.1 | D29: =IF(ISBLANK(C29),B29,C29) | E29: % | F29: assumption | G29: ±10% treated as fairly valued
A30: Years for price to converge to value | B30: 1 | D30: =IF(ISBLANK(C30),B30,C30) | E30: yrs | F30: assumption | G30: convergence horizon
A31: Peer regression used only if R² is at least | B31: 0.3 | D31: =IF(ISBLANK(C31),B31,C31) | F31: setting
A32: Earnings-quality gate (1 = grade D withholds the call) | B32: 1 | D32: =IF(ISBLANK(C32),B32,C32) | F32: setting
A33: Operating
A34: Last fiscal-year revenue | B34: 20248 | D34: =IF(ISBLANK(C34),B34,C34) | E34: $m | F34: sourced | G34: Yahoo Finance fundamentals (annual) TotalRevenue, 2026-06-30
A35: Corporate costs % revenue | B35: 0 | D35: =IF(ISBLANK(C35),B35,C35) | E35: % | F35: assumption | G35: none (single segment)
A36: Tax rate, year 1 | B36: 0.12168702 | D36: =IF(ISBLANK(C36),B36,C36) | E36: % | F36: derived | G36: Yahoo Finance fundamentals (annual) TaxProvision ÷ PretaxIncome (clamped 10–30%)
A37: Tax rate, long run (from year 5) | B37: 0.18 | D37: =IF(ISBLANK(C37),B37,C37) | E37: % | F37: assumption | G37: max(effective rate, 18%)
A38: D&A % revenue | B38: 0.015642328 | D38: =IF(ISBLANK(C38),B38,C38) | E38: % | F38: derived | G38: Yahoo Finance fundamentals (annual) D&A ÷ revenue, 3-year average
A39: Capex % revenue | B39: 0.015963346 | D39: =IF(ISBLANK(C39),B39,C39) | E39: % | F39: derived | G39: Yahoo Finance fundamentals (annual) capex ÷ revenue, 3-year average
A40: ΔNWC % of Δrevenue | B40: 0.19213608 | D40: =IF(ISBLANK(C40),B40,C40) | E40: % | F40: derived | G40: Yahoo Finance fundamentals (quarterly) (receivables + inventory − payables) ÷ (4 × revenue), quarter to 2026-06-30
A41: Working capital at the last balance sheet | B41: 6890 | D41: =IF(ISBLANK(C41),B41,C41) | E41: $m | F41: derived | G41: Yahoo Finance fundamentals (quarterly) receivables + inventory − payables, 2026-06-30; year 1 change = NWC % × revenue − this level
...

Sheet Scenarios
A1: Scenarios | C1: ="Scenario: "&scen_name&" · switch on Dashboard"
A2: Blue cells are the drivers for each case; column E is the case picked by the switch on the Dashboard.
A4: Driver | B4: Bear | C4: Base | D4: Bull | E4: Used | F4: Notes
A5: Revenue growth: Total revenue, year 2 | B5: 0.13928929 | C5: 0.18928929 | D5: 0.22928929 | E5: =CHOOSE(scen_sel,B5,C5,D5) | F5: consensus: FY28 ÷ FY27 revenue estimate − 1
A6: Revenue growth: Total revenue, year 3 | B6: 0.11446697 | C6: 0.15196697 | D6: 0.18196697 | E6: =CHOOSE(scen_sel,B6,C6,D6) | F6: fade: g×0.75+1%, g×0.5+1.5%, g×0.35+2%
A7: Revenue growth: Total revenue, year 4 | B7: 0.084644647 | C7: 0.10964465 | D7: 0.12964465 | E7: =CHOOSE(scen_sel,B7,C7,D7) | F7: fade: g×0.75+1%, g×0.5+1.5%, g×0.35+2%
A8: Revenue growth: Total revenue, year 5 | B8: 0.068751253 | C8: 0.086251253 | D8: 0.10025125 | E8: =CHOOSE(scen_sel,B8,C8,D8) | F8: fade: g×0.75+1%, g×0.5+1.5%, g×0.35+2%
A9: EBIT margin: Company EBIT margin, year 1 | B9: 0.61576452 | C9: 0.77567185 | D9: 0.77567185 | E9: =CHOOSE(scen_sel,B9,C9,D9) | F9: Yahoo Finance quoteSummary consensus FY27 EPS × diluted shares ÷ (1 − tax) + interest, ÷ consensus revenue (consensus EPS may be on an adjusted basis)
A10: EBIT margin: Company EBIT margin, long run (from year 5) | B10: 0.10131928 | C10: 0.3585419 | D10: 0.61576452 | E10: =CHOOSE(scen_sel,B10,C10,D10) | F10: midpoint of TTM and multi-year average margin

Sheet 1 History
A1: Step 1 · Historic performance | C1: ="Scenario: "&scen_name&" · switch on Dashboard"
A2: Reported figures ($m) as pulled; growth and margins are formulas. Earnings quality below.
A4: Line | B4: FY23 | C4: FY24 | D4: FY25 | E4: FY26
A5: Revenue | B5: 6086 | C5: 6663 | D5: 7355 | E5: 20248
A6: Operating income | B6: -1295 | C6: -444 | D6: 507 | E6: 12468
A7: Net income | B7: -2143 | C7: -672 | D7: -1641 | E7: 11433
A8: Diluted EPS | B8: -14.78 | C8: -4.63 | D8: -11.32
A9: Cash from operations | B9: -713 | C9: -309 | D9: 84 | E9: 11671
A10: Capex | B10: 219 | C10: 166 | D10: 204 | E10: 177
A11: Free cash flow | B11: -932 | C11: -475 | D11: -120 | E11: 11494
A12: Revenue growth | C12: =IF(AND(ISNUMBER(B5),ISNUMBER(C5)),C5/B5-1,"") | D12: =IF(AND(ISNUMBER(C5),ISNUMBER(D5)),D5/C5-1,"") | E12: =IF(AND(ISNUMBER(D5),ISNUMBER(E5)),E5/D5-1,"")
A13: Operating income ÷ revenue | B13: =IF(AND(ISNUMBER(B6),ISNUMBER(B5)),B6/B5,"") | C13: =IF(AND(ISNUMBER(C6),ISNUMBER(C5)),C6/C5,"") | D13: =IF(AND(ISNUMBER(D6),ISNUMBER(D5)),D6/D5,"") | E13: =IF(AND(ISNUMBER(E6),ISNUMBER(E5)),E6/E5,"")
A14: Net income ÷ revenue | B14: =IF(AND(ISNUMBER(B7),ISNUMBER(B5)),B7/B5,"") | C14: =IF(AND(ISNUMBER(C7),ISNUMBER(C5)),C7/C5,"") | D14: =IF(AND(ISNUMBER(D7),ISNUMBER(D5)),D7/D5,"") | E14: =IF(AND(ISNUMBER(E7),ISNUMBER(E5)),E7/E5,"")
A15: Cash from operations ÷ revenue | B15: =IF(AND(ISNUMBER(B9),ISNUMBER(B5)),B9/B5,"") | C15: =IF(AND(ISNUMBER(C9),ISNUMBER(C5)),C9/C5,"") | D15: =IF(AND(ISNUMBER(D9),ISNUMBER(D5)),D9/D5,"") | E15: =IF(AND(ISNUMBER(E9),ISNUMBER(E5)),E9/E5,"")
A16: Yahoo Finance standardised statements. Operating income can differ from the company's GAAP line where Yahoo normalises unusual items.
A18: Earnings quality: are the earnings backed by cash?
A19: Statement line ($m) | B19: FY23 | C19: FY24 | D19: FY25 | E19: FY26
A20: Revenue | B20: 6086 | C20: 6663 | D20: 7355 | E20: 20248
A21: Cost of revenue | B21: 5656 | C21: 5591 | D21: 5143 | E21: 5776
A22: SG&A | B22: 558 | C22: 455 | D22: 573 | E22: 676
A23: Receivables | C23: 935 | D23: 1068 | E23: 4708
A24: Current assets | C24: 3548 | D24: 5086 | E24: 12780
A25: Net PP&E | C25: 791 | D25: 619 | E25: 674
A26: Total assets | C26: 13506 | D26: 12985 | E26: 22507
A27: Current liabilities | C27: 2123 | D27: 1427 | E27: 5581
A28: Long-term debt | D28: 1829
A29: Depreciation & amortisation | B29: 448 | C29: 224 | D29: 163 | E29: 149
A30: Net income (continuing) | B30: -2143 | C30: -672 | D30: -1641 | E30: 11433
A31: Operating cash flow | B31: -713 | C31: -309 | D31: 84 | E31: 11671
A32: Yahoo Finance fundamentals (annual): revenue, cost of revenue, SG&A, receivables, current assets, net PP&E, total assets, current liabilities, long-term debt, D&A, net income (continuing), operating cash flow
A34: Beneish index (blank = input missing; set to 1 in the score) | B34: FY24 | C34: FY25 | D34: FY26 | E34: Coefficient | F34: Manipulators' mean
A35: DSRI: Days sales in receivables | B35: =IF(COUNT(C23,C20,B23,B20)=4,(C23/C20)/(B23/B20),NA()) | C35: =IF(COUNT(D23,D20,C23,C20)=4,(D23/D20)/(C23/C20),NA()) | D35: =IF(COUNT(E23,E20,D23,D20)=4,(E23/E20)/(D23/D20),NA()) | E35: 0.92 | F35: 1.465
A36: GMI: Gross margin, prior ÷ current | B36: =IF(COUNT(C20,C21,B20,B21)=4,((B20-B21)/B20)/((C20-C21)/C20),NA()) | C36: =IF(COUNT(D20,D21,C20,C21)=4,((C20-C21)/C20)/((D20-D21)/D20),NA()) | D36: =IF(COUNT(E20,E21,D20,D21)=4,((D20-D21)/D20)/((E20-E21)/E20),NA()) | E36: 0.528 | F36: 1.193
A37: AQI: Asset quality | B37: =IF(COUNT(C24,C25,C26,B24,B25,B26)=6,(1-(C24+C25)/C26)/(1-(B24+B25)/B26),NA()) | C37: =IF(COUNT(D24,D25,D26,C24,C25,C26)=6,(1-(D24+D25)/D26)/(1-(C24+C25)/C26),NA()) | D37: =IF(COUNT(E24,E25,E26,D24,D25,D26)=6,(1-(E24+E25)/E26)/(1-(D24+D25)/D26),NA()) | E37: 0.404 | F37: 1.254
A38: SGI: Sales growth | B38: =IF(COUNT(C20,B20)=2,C20/B20,NA()) | C38: =IF(COUNT(D20,C20)=2,D20/C20,NA()) | D38: =IF(COUNT(E20,D20)=2,E20/D20,NA()) | E38: 0.892 | F38: 1.607
A39: DEPI: Depreciation rate, prior ÷ current | B39: =IF(COUNT(C29,C25,B29,B25)=4,(B29/(B29+B25))/(C29/(C29+C25)),NA()) | C39: =IF(COUNT(D29,D25,C29,C25)=4,(C29/(C29+C25))/(D29/(D29+D25)),NA()) | D39: =IF(COUNT(E29,E25,D29,D25)=4,(D29/(D29+D25))/(E29/(E29+E25)),NA()) | E39: 0.115 | F39: 1.077
A40: SGAI: SG&A ÷ sales | B40: =IF(COUNT(C22,C20,B22,B20)=4,(C22/C20)/(B22/B20),NA()) | C40: =IF(COUNT(D22,D20,C22,C20)=4,(D22/D20)/(C22/C20),NA()) | D40: =IF(COUNT(E22,E20,D22,D20)=4,(E22/E20)/(D22/D20),NA()) | E40: -0.172 | F40: 1.041
A41: LVGI: Leverage | B41: =IF(COUNT(C27,C28,C26,B27,B28,B26)=6,((C27+C28)/C26)/((B27+B28)/B26),NA()) | C41: =IF(COUNT(D27,D28,D26,C27,C28,C26)=6,((D27+D28)/D26)/((C27+C28)/C26),NA()) | D41: =IF(COUNT(E27,E28,E26,D27,D28,D26)=6,((E27+E28)/E26)/((D27+D28)/D26),NA()) | E41: -0.327 | F41: 1.111
A42: TATA: Accruals ÷ total assets | B42: =IF(COUNT(C30,C31,C26)=3,(C30-C31)/C26,NA()) | C42: =IF(COUNT(D30,D31,D26)=3,(D30-D31)/D26,NA()) | D42: =IF(COUNT(E30,E31,E26)=3,(E30-E31)/E26,NA()) | E42: 4.679 | F42: 0.031
A43: M-score = −4.84 + Σ coefficient × index | B43: =IF(OR(ISERROR(B42),(ISERROR(B35)+ISERROR(B36)+ISERROR(B37)+ISERROR(B38)+ISERROR(B39)+ISERROR(B40)+ISERROR(B41))>2),NA(),-4.84+E35*IFERROR(B35,1)+E36*IFERROR(B36,1)+E37*IFERROR(B37,1)+E38*IFERROR(B38,1)+E39*IFERROR(B39,1)+E40*IFERROR(B40,1)+E41*IFERROR(B41,1)+E42*B42) | C43: =IF(OR(ISERROR(C42),(ISERROR(C35)+ISERROR(C36)+ISERROR(C37)+ISERROR(C38)+ISERROR(C39)+ISERROR(C40)+ISERROR(C41))>2),NA(),-4.84+E35*IFERROR(C35,1)+E36*IFERROR(C36,1)+E37*IFERROR(C37,1)+E38*IFERROR(C38,1)+E39*IFERROR(C39,1)+E40*IFERROR(C40,1)+E41*IFERROR(C41,1)+E42*C42) | D43: =IF(OR(ISERROR(D42),(ISERROR(D35)+ISERROR(D36)+ISERROR(D37)+ISERROR(D38)+ISERROR(D39)+ISERROR(D40)+ISERROR(D41))>2),NA(),-4.84+E35*IFERROR(D35,1)+E36*IFERROR(D36,1)+E37*IFERROR(D37,1)+E38*IFERROR(D38,1)+E39*IFERROR(D39,1)+E40*IFERROR(D40,1)+E41*IFERROR(D41,1)+E42*D42)
...

Sheet 2 Cash flows
A1: Step 2 · Future cash flows | C1: ="Scenario: "&scen_name&" · switch on Dashboard"
A2: Revenue by segment → EBIT → NOPAT → + D&A − capex − ΔNWC = unlevered free cash flow ($m)
A4: Line | B4: Total | C4: How it is calculated | D4: FY27 | E4: FY28 | F4: FY29 | G4: FY30 | H4: FY31 | I4: FY32 | J4: FY33 | K4: FY34 | L4: FY35 | M4: FY36
A5: Year index i | D5: 0 | E5: 1 | F5: 2 | G5: 3 | H5: 4 | I5: 5 | J5: 6 | K5: 7 | L5: 8 | M5: 9
A6: Growth: Total revenue | C6: years 2–5 from Scenarios; then linear fade to terminal g over 5 years | E6: =s_g_total_0 | F6: =s_g_total_1 | G6: =s_g_total_2 | H6: =s_g_total_3 | I6: =s_g_total_3+(g-s_g_total_3)*(I$5-4)/5 | J6: =s_g_total_3+(g-s_g_total_3)*(J$5-4)/5 | K6: =s_g_total_3+(g-s_g_total_3)*(K$5-4)/5 | L6: =s_g_total_3+(g-s_g_total_3)*(L$5-4)/5 | M6: =s_g_total_3+(g-s_g_total_3)*(M$5-4)/5
A7: Revenue: Total revenue | C7: year 1 from Inputs; then prior × (1 + growth) | D7: =segy1_total | E7: =D7*(1+E6) | F7: =E7*(1+F6) | G7: =F7*(1+G6) | H7: =G7*(1+H6) | I7: =H7*(1+I6) | J7: =I7*(1+J6) | K7: =J7*(1+K6) | L7: =K7*(1+L6) | M7: =L7*(1+M6)
A8: EBIT margin: Company EBIT margin | C8: year 1 → long run in a straight line over 4 years, flat after | D8: =IF(D$5>=4,s_m1_total,s_m0_total+(s_m1_total-s_m0_total)*D$5/4) | E8: =IF(E$5>=4,s_m1_total,s_m0_total+(s_m1_total-s_m0_total)*E$5/4) | F8: =IF(F$5>=4,s_m1_total,s_m0_total+(s_m1_total-s_m0_total)*F$5/4) | G8: =IF(G$5>=4,s_m1_total,s_m0_total+(s_m1_total-s_m0_total)*G$5/4) | H8: =IF(H$5>=4,s_m1_total,s_m0_total+(s_m1_total-s_m0_total)*H$5/4) | I8: =IF(I$5>=4,s_m1_total,s_m0_total+(s_m1_total-s_m0_total)*I$5/4) | J8: =IF(J$5>=4,s_m1_total,s_m0_total+(s_m1_total-s_m0_total)*J$5/4) | K8: =IF(K$5>=4,s_m1_total,s_m0_total+(s_m1_total-s_m0_total)*K$5/4) | ... M8: =IF(M$5>=4,s_m1_total,s_m0_total+(s_m1_total-s_m0_total)*M$5/4)
A9: Revenue | B9: =SUM(D9:M9) | C9: sum of segments | D9: =D7 | E9: =E7 | F9: =F7 | G9: =G7 | H9: =H7 | I9: =I7 | J9: =J7 | K9: =K7 | ... M9: =M7
A10: Revenue growth | C10: revenue ÷ prior − 1 (year 1 vs last reported year) | D10: =D9/rev_y0-1 | E10: =E9/D9-1 | F10: =F9/E9-1 | G10: =G9/F9-1 | H10: =H9/G9-1 | I10: =I9/H9-1 | J10: =J9/I9-1 | K10: =K9/J9-1 | L10: =L9/K9-1 | M10: =M9/L9-1
A11: Segment operating income | C11: Σ segment revenue × its margin group | D11: =D7*D8 | E11: =E7*E8 | F11: =F7*F8 | G11: =G7*G8 | H11: =H7*H8 | I11: =I7*I8 | J11: =J7*J8 | K11: =K7*K8 | ... M11: =M7*M8
A12: − Corporate costs (SBC, amortisation, other) | C12: corporate % × revenue | D12: =corp_pct*D9 | E12: =corp_pct*E9 | F12: =corp_pct*F9 | G12: =corp_pct*G9 | H12: =corp_pct*H9 | I12: =corp_pct*I9 | J12: =corp_pct*J9 | K12: =corp_pct*K9 | ... M12: =corp_pct*M9
A13: EBIT | B13: =SUM(D13:M13) | C13: segment OI − corporate costs | D13: =D11-D12 | E13: =E11-E12 | F13: =F11-F12 | G13: =G11-G12 | H13: =H11-H12 | I13: =I11-I12 | J13: =J11-J12 | K13: =K11-K12 | ... M13: =M11-M12
A14: EBIT margin | C14: EBIT ÷ revenue | D14: =D13/D9 | E14: =E13/E9 | F14: =F13/F9 | G14: =G13/G9 | H14: =H13/H9 | I14: =I13/I9 | J14: =J13/J9 | K14: =K13/K9 | ... M14: =M13/M9
A15: Tax rate | C15: year 1 → long run over 4 years | D15: =IF(D$5>=4,tax_lr,tax_y1+(tax_lr-tax_y1)*D$5/4) | E15: =IF(E$5>=4,tax_lr,tax_y1+(tax_lr-tax_y1)*E$5/4) | F15: =IF(F$5>=4,tax_lr,tax_y1+(tax_lr-tax_y1)*F$5/4) | G15: =IF(G$5>=4,tax_lr,tax_y1+(tax_lr-tax_y1)*G$5/4) | H15: =IF(H$5>=4,tax_lr,tax_y1+(tax_lr-tax_y1)*H$5/4) | I15: =IF(I$5>=4,tax_lr,tax_y1+(tax_lr-tax_y1)*I$5/4) | J15: =IF(J$5>=4,tax_lr,tax_y1+(tax_lr-tax_y1)*J$5/4) | K15: =IF(K$5>=4,tax_lr,tax_y1+(tax_lr-tax_y1)*K$5/4) | ... M15: =IF(M$5>=4,tax_lr,tax_y1+(tax_lr-tax_y1)*M$5/4)
A16: NOPAT | C16: EBIT × (1 − tax) | D16: =D13*(1-D15) | E16: =E13*(1-E15) | F16: =F13*(1-F15) | G16: =G13*(1-G15) | H16: =H13*(1-H15) | I16: =I13*(1-I15) | J16: =J13*(1-J15) | K16: =K13*(1-K15) | ... M16: =M13*(1-M15)
A17: + D&A | C17: D&A % × revenue | D17: =da_pct*D9 | E17: =da_pct*E9 | F17: =da_pct*F9 | G17: =da_pct*G9 | H17: =da_pct*H9 | I17: =da_pct*I9 | J17: =da_pct*J9 | K17: =da_pct*K9 | ... M17: =da_pct*M9
A18: − Capex | C18: capex % × revenue | D18: =capex_pct*D9 | E18: =capex_pct*E9 | F18: =capex_pct*F9 | G18: =capex_pct*G9 | H18: =capex_pct*H9 | I18: =capex_pct*I9 | J18: =capex_pct*J9 | K18: =capex_pct*K9 | ... M18: =capex_pct*M9
A19: − Change in working capital | C19: yr 1: NWC % × revenue − opening NWC; then NWC % × Δrevenue | D19: =nwc_pct*D9-nwc_open | E19: =nwc_pct*(E9-D9) | F19: =nwc_pct*(F9-E9) | G19: =nwc_pct*(G9-F9) | H19: =nwc_pct*(H9-G9) | I19: =nwc_pct*(I9-H9) | J19: =nwc_pct*(J9-I9) | K19: =nwc_pct*(K9-J9) | L19: =nwc_pct*(L9-K9) | M19: =nwc_pct*(M9-L9)
A20: Unlevered free cash flow (FCFF) | B20: =SUM(D20:M20) | C20: NOPAT + D&A − capex − ΔNWC | D20: =D16+D17-D18-D19 | E20: =E16+E17-E18-E19 | F20: =F16+F17-F18-F19 | G20: =G16+G17-G18-G19 | H20: =H16+H17-H18-H19 | I20: =I16+I17-I18-I19 | J20: =J16+J17-J18-J19 | K20: =K16+K17-K18-K19 | ... M20: =M16+M17-M18-M19
A21: EBITDA | C21: EBIT + D&A | D21: =D13+D17 | E21: =E13+E17 | F21: =F13+F17 | G21: =G13+G17 | H21: =H13+H17 | I21: =I13+I17 | J21: =J13+J17 | K21: =K13+K17 | ... M21: =M13+M17

Sheet 3 Discount rate
A1: Step 3 · Discount rate | C1: ="Scenario: "&scen_name&" · switch on Dashboard"
A2: Cost of equity from CAPM with a beta regressed on daily returns; then debt and WACC.
A4: Item | B4: Value | C4: How it is calculated
A5: Cost of equity
A6: 1 · Risk-free rate (10-year Treasury) | B6: =rf | C6: Inputs
A7: 2 · Expected market return (Rm) | B7: =rm | C7: Inputs
A8: 3 · Market risk premium = Rm − rf | B8: =rm-rf | C8: Rm − rf
A9: 4a · Daily regression beta = SLOPE(stock returns, index returns) | B9: =SLOPE(beta_rs,beta_rm) | C9: OLS slope on the Beta data sheet
A10: R² of the regression | B10: =RSQ(beta_rs,beta_rm) | C10: share of the stock's daily moves explained by the market
A11: Standard error of beta | B11: =STEYX(beta_rs,beta_rm)/SQRT(DEVSQ(beta_rm)) | C11: s ÷ √Σ(x − x̄)²
A12: Number of daily returns | B12: =COUNT(beta_rs)
A13: Daily beta carried forward | B13: =IF(ISNUMBER(beta_reg),beta_reg,beta_daily_in)
A14: 4b · Beta used | B14: =IF(beta_src="raw",beta_raw,IF(beta_src="bottom_up",beta_bu,IF(beta_src="custom",beta_custom,IF(AND(beta_src="daily",ISNUMBER(beta_daily)),beta_daily,IF(AND(beta_src="daily_adj",ISNUMBER(beta_daily)),0.67*beta_daily+0.33,IF(AND(beta_src="crsp_monthly",ISNUMBER(beta_crsp)),beta_crsp,IF(AND(beta_src="crsp_monthly_adj",ISNUMBER(beta_crsp)),0.67*beta_crsp+0.33,0.67*beta_raw+0.33))))))) | C14: source chosen on Inputs; _adj = Blume 0.67 × β + 0.33
A15: 5 · Equity risk premium for this stock = β × MRP | B15: =beta_used*mrp | C15: beta × (Rm − rf)
A16: 6 · Cost of equity Ke = rf + β × MRP + CRP + size | B16: =rf+eq_prem+crp+size_prem | C16: the discount rate for equity holders
A17: Cost of debt and WACC
A18: After-tax cost of debt = Kd × (1 − t) | B18: =kd*(1-t_marg)
A19: Equity at market value, $m | B19: =px_now*(shares_basic+dilution) | C19: price × diluted shares
A20: Debt including leases, $m | B20: =core_debt+leases | C20: book value
A21: Weight of equity E ÷ (D + E) | B21: =e_val/(e_val+d_val)
A22: Weight of debt D ÷ (D + E) | B22: =d_val/(e_val+d_val)
A23: WACC = wE × Ke + wD × Kd(1 − t) | B23: =w_e*ke+w_d*kd_after | C23: the discount rate for the whole firm
A24: Discount rate used in step 4 (WACC) | B24: =wacc

Sheet 4 Discount
A1: Step 4 · Discount the cash flows | C1: ="Scenario: "&scen_name&" · switch on Dashboard"
A2: PV = cash flow × (1 + r)^−t, with r from step 3; then the terminal value.
A4: Line | B4: Total | C4: How it is calculated | D4: FY27 | E4: FY28 | F4: FY29 | G4: FY30 | H4: FY31 | I4: FY32 | J4: FY33 | K4: FY34 | L4: FY35 | M4: FY36
A5: Year index i | D5: 0 | E5: 1 | F5: 2 | G5: 3 | H5: 4 | I5: 5 | J5: 6 | K5: 7 | L5: 8 | M5: 9
A6: FCFF (full year) | C6: from step 2 | D6: ='2 Cash flows'!D20 | E6: ='2 Cash flows'!E20 | F6: ='2 Cash flows'!F20 | G6: ='2 Cash flows'!G20 | H6: ='2 Cash flows'!H20 | I6: ='2 Cash flows'!I20 | J6: ='2 Cash flows'!J20 | K6: ='2 Cash flows'!K20 | ... M6: ='2 Cash flows'!M20
A7: Share of the year counted | C7: year 1: only the part after the last balance sheet (the rest is in today's cash) | D7: =stub | E7: =1 | F7: =1 | G7: =1 | H7: =1 | I7: =1 | J7: =1 | K7: =1 | L7: =1 | M7: =1
A8: FCFF counted | C8: FCFF × share of year | D8: =D6*D7 | E8: =E6*E7 | F8: =F6*F7 | G8: =G6*G7 | H8: =H6*H7 | I8: =I6*I7 | J8: =J6*J7 | K8: =K6*K7 | ... M8: =M6*M7
A9: Years from today (t) | C9: first fiscal year end + i, less half a year's share if mid-year | D9: =MAX(IF(midyear=1,first_period+D$5-0.5*D7,first_period+D$5),0) | E9: =MAX(IF(midyear=1,first_period+E$5-0.5*E7,first_period+E$5),0) | F9: =MAX(IF(midyear=1,first_period+F$5-0.5*F7,first_period+F$5),0) | G9: =MAX(IF(midyear=1,first_period+G$5-0.5*G7,first_period+G$5),0) | H9: =MAX(IF(midyear=1,first_period+H$5-0.5*H7,first_period+H$5),0) | I9: =MAX(IF(midyear=1,first_period+I$5-0.5*I7,first_period+I$5),0) | J9: =MAX(IF(midyear=1,first_period+J$5-0.5*J7,first_period+J$5),0) | K9: =MAX(IF(midyear=1,first_period+K$5-0.5*K7,first_period+K$5),0) | ... M9: =MAX(IF(midyear=1,first_period+M$5-0.5*M7,first_period+M$5),0)
A10: Discount factor | C10: (1 + r)^−t | D10: =(1+disc_rate)^(-D9) | E10: =(1+disc_rate)^(-E9) | F10: =(1+disc_rate)^(-F9) | G10: =(1+disc_rate)^(-G9) | H10: =(1+disc_rate)^(-H9) | I10: =(1+disc_rate)^(-I9) | J10: =(1+disc_rate)^(-J9) | K10: =(1+disc_rate)^(-K9) | ... M10: =(1+disc_rate)^(-M9)
A11: Present value | B11: =SUM(D11:M11) | C11: counted × discount factor | D11: =D8*D10 | E11: =E8*E10 | F11: =F8*F10 | G11: =G8*G10 | H11: =H8*H10 | I11: =I8*I10 | J11: =J8*J10 | K11: =K8*K10 | ... M11: =M8*M10
A13: Years to the last forecast year end | B13: =first_period+9
A14: Terminal value, value driver = NOPAT × (1 + g) × (1 − g ÷ RONIC) ÷ (WACC − g) | B14: =cf_last_nopat*(1+g)*(1-g/ronic)/(disc_rate-g) | C14: growth needs reinvestment: g ÷ RONIC of NOPAT is reinvested
A15: PV of value-driver terminal value | B15: =tv_gordon*(1+disc_rate)^(-IF(midyear=1,t_n-0.5,t_n))
A16: Terminal value, exit multiple × last EBITDA | B16: =exit_mult*cf_last_ebitda | C16: cross-check
A17: PV of exit terminal value | B17: =tv_exit*(1+disc_rate)^(-t_n)
A18: PV of the terminal value used | B18: =IF(tv_method="exit",pv_exit,pv_gordon) | C18: method on Inputs
A19: Enterprise value = Σ PV + PV of terminal value | B19: =pv_sum+pv_tv
A20: Terminal value share of EV | B20: =pv_tv/ev

Sheet 5 Price
A1: Step 5 · From value to the share price | C1: ="Scenario: "&scen_name&" · switch on Dashboard"
A2: Enterprise value − debt + cash (and other claims) = equity value, the estimated market cap; ÷ diluted shares = fair price.
A4: Item | B4: Value | C4: How it is calculated
A5: Enterprise value (step 4) | B5: =ev
A6: − Debt excluding leases | B6: =-core_debt | C6: Inputs
A7: − Lease liabilities | B7: =-leases | C7: Inputs
A8: + Cash | B8: =cash | C8: Inputs
A9: + Captive-finance net assets (receivables + equipment − its own debt) | B9: =dfs_rec+dfs_le-dfs_debt | C9: financing arms are added at net book value
A10: + Non-operating investments | B10: =investments | C10: Inputs
A11: − Non-controlling interests | B11: =-nci | C11: Inputs
A12: Equity value (estimated market cap) | B12: =ev_x+x_debt+x_leases+x_cash+dfs_net+x_inv+x_nci
A13: Diluted shares (m) = shares outstanding + dilution | B13: =shares_basic+dilution | C13: Inputs
A14: Fair share price (this scenario) | B14: =equity/dil_sh | C14: equity value ÷ diluted shares
A15: Share price today | B15: =px_now
A16: Upside / (downside) | B16: =model_ps/x_price-1
A17: Market cap today | B17: =px_now*dil_sh
A18: Estimated vs actual market cap | B18: =equity/mcap_now-1

Sheet 6 Verdict
A1: Step 6 · Verdict | C1: ="Scenario: "&scen_name&" · switch on Dashboard"
A2: Methods blended by weight; methods that give no value drop out. The call needs the blend to differ from the price by more than the band.
A4: Method | B4: Value / share | C4: Weight | D4: vs price | E4: Weight × value | F4: Weight counted | G4: How it is computed
A5: DCF (FCFF), this scenario | B5: =model_ps | C5: 0.4 | D5: =IF(ISNUMBER(B5),B5/px_now-1,"") | E5: =IF(ISNUMBER(B5),B5*C5,0) | F5: =IF(ISNUMBER(B5),C5,0) | G5: steps 2–5
A6: Monte Carlo median | B6: 1452.2996 | C6: 0.2 | D6: =IF(ISNUMBER(B6),B6/px_now-1,"") | E6: =IF(ISNUMBER(B6),B6*C6,0) | F6: =IF(ISNUMBER(B6),C6,0) | G6: value from the Python engine: 5,000 model runs with random drivers, discount rate and g (not a formula)
A7: Comps blend | B7: =comps_ps | C7: 0.3 | D7: =IF(ISNUMBER(B7),B7/px_now-1,"") | E7: =IF(ISNUMBER(B7),B7*C7,0) | F7: =IF(ISNUMBER(B7),C7,0) | G7: Comps sheet
A8: Peer regression | B8: =reg_ps | C8: 0.1 | D8: =IF(ISNUMBER(B8),B8/px_now-1,"") | E8: =IF(ISNUMBER(B8),B8*C8,0) | F8: =IF(ISNUMBER(B8),C8,0) | G8: Comps sheet
A10: Blended fair value = Σ weight × value ÷ Σ weight counted | B10: =SUM(E5:E8)/SUM(F5:F8)
A11: Upside / (downside) vs price | B11: =fair/px_now-1
A12: Earnings-quality grade (step 1) | B12: =eq_grade
A13: Call before the quality gate | B13: =IF(upside>band,"UNDERVALUED",IF(upside<-band,"OVERVALUED","FAIRLY VALUED"))
A14: Call | B14: =IF(AND(eq_gate=1,eq_grade_x="D"),"NO CALL",raw_call)
A15: Confidence | B15: =IF(AND(eq_gate=1,eq_grade_x="C"),"low","normal")
A16: Expected 1-year return = (fair ÷ price)^(1 ÷ horizon) − 1 + dividend yield | B16: =(fair/px_now)^(1/horizon)-1+dps/px_now
A17: Required return (Ke, step 3) | B17: =ke
A18: Expected alpha = expected − required | B18: =exp_ret-req_ret
A20: Python engine at build (2026-10-20): fair 1315.1733, FAIRLY VALUED. Tests recalculate this workbook and require the same numbers.

Sheet Comps
A1: Comps | C1: ="Scenario: "&scen_name&" · switch on Dashboard"
A2: Peer multiples from the data feed (blue, editable). Non-positive multiples are left blank, so they drop out of the statistic.
A4: Peer | B4: Name | C4: Forward P/E
A5: 000660.KS | B5: SK hynix Inc. | C5: 2.6145825
A6: 005930.KS | B6: Samsung Electronics Co., Ltd. | C6: 2.9177794
A7: 285A.T | B7: Kioxia Holdings Corporation
A8: MU | B8: Micron Technology, Inc. | C8: 4.3310623
A9: STX | B9: Seagate Technology Holdings plc | C9: 11.847629
A10: WDC | B10: Western Digital Corporation | C10: 10.948699
A12: Company metrics
A13: Forward EPS (consensus) | C13: 266.2971
A14: EBITDA, trailing 12 months ($m) | C14: 12617
A15: Revenue, trailing 12 months ($m) | C15: 20248.001
A16: Net debt on the vendor's basis: all debt + leases − cash ($m) | C16: -4408
A19: Multiple | C19: Peer median | D19: Company today | E19: Implied price | F19: Weight | G19: Weight × price
A20: Forward P/E | C20: =IFERROR(MEDIAN(C5:C10),NA()) | D20: =IFERROR(px_now/c_eps,NA()) | E20: =IFERROR(C20*c_eps,NA()) | F20: 1 | G20: =IF(ISNUMBER(E20),E20*F20,0)
A21: Blended comps value = Σ weight × price ÷ Σ weight of the multiples that worked | E21: =IF(SUMPRODUCT(--ISNUMBER(E20:E20),F20:F20)>0,SUM(G20:G20)/SUMPRODUCT(--ISNUMBER(E20:E20),F20:F20),NA())
A24: Peer regression: forward P/E on 3-year EPS growth
A25: Peer | C25: x: EPS growth | D25: y: Fwd P/E
A26: 000660.KS | C26: 0.3195 | D26: 2.6145825
A27: 005930.KS | C27: 0.5143 | D27: 2.9177794
A28: MU | C28: 0.1719 | D28: 4.3310623
A29: STX | C29: 0.57 | D29: 11.847629
A30: WDC | C30: 0.616 | D30: 10.948699
A32: Slope b = SLOPE(y, x) | E32: =SLOPE(D26:D30,C26:C30)
A33: Intercept a = INTERCEPT(y, x) | E33: =INTERCEPT(D26:D30,C26:C30)
A34: R² | E34: =RSQ(D26:D30,C26:C30)
A35: Peers in the fit | E35: =COUNT(C26:C30)
A36: Company EPS growth used: consensus EPS growth (Inputs file) | E36: 0.23959999
A37: Fitted multiple = a + b × company growth | E37: =reg_a+reg_b*c_growth
A38: Regression value per share (blank if R² is below the minimum on Inputs) | E38: =IF(AND(reg_n>=3,reg_r2>=reg_min),reg_mult*c_eps,"")

Sheet Beta data
A1: Beta data
A2: Daily adjusted closes for SNDK and the S&P 500; returns are formulas. Paste a longer or different window to change the beta. | G2: 2025-02-14 to 2026-10-20
A4: Date | B4: SNDK | C4: S&P 500 | D4: Stock return | E4: Index return
A5: 2025-02-13 | B5: 36 | C5: 6115.0698
A6: 2025-02-14 | B6: 36.650002 | C6: 6114.6299 | D6: =B6/B5-1 | E6: =C6/C5-1
A7: 2025-02-18 | B7: 47.150002 | C7: 6129.5801 | D7: =B7/B6-1 | E7: =C7/C6-1
A8: 2025-02-19 | B8: 46 | C8: 6144.1499 | D8: =B8/B7-1 | E8: =C8/C7-1
A9: 2025-02-20 | B9: 48.259998 | C9: 6117.52 | D9: =B9/B8-1 | E9: =C9/C8-1
A10: 2025-02-21 | B10: 50.369999 | C10: 6013.1299 | D10: =B10/B9-1 | E10: =C10/C9-1
A11: 2025-02-24 | B11: 48.599998 | C11: 5983.25 | D11: =B11/B10-1 | E11: =C11/C10-1
A12: 2025-02-25 | B12: 48.16 | C12: 5955.25 | D12: =B12/B11-1 | E12: =C12/C11-1
A13: 2025-02-26 | B13: 46.580002 | C13: 5956.0601 | D13: =B13/B12-1 | E13: =C13/C12-1
A14: 2025-02-27 | B14: 45.16 | C14: 5861.5698 | D14: =B14/B13-1 | E14: =C14/C13-1
A15: 2025-02-28 | B15: 46.849998 | C15: 5954.5 | D15: =B15/B14-1 | E15: =C15/C14-1
A16: 2025-03-03 | B16: 50.310001 | C16: 5849.7202 | D16: =B16/B15-1 | E16: =C16/C15-1
A17: 2025-03-04 | B17: 48.689999 | C17: 5778.1499 | D17: =B17/B16-1 | E17: =C17/C16-1
... A427: 2026-10-20 | B427: 1365.38 | C427: 7712.5698 | D427: =B427/B426-1 | E427: =C427/C426-1
